Traceback (most recent call last):
  File "/opt/hostedtoolcache/Python/3.9.16/x64/lib/python3.9/site-packages/jupyter_cache/executors/utils.py", line 58, in single_nb_execution
    executenb(
  File "/opt/hostedtoolcache/Python/3.9.16/x64/lib/python3.9/site-packages/nbclient/client.py", line 1305, in execute
    return NotebookClient(nb=nb, resources=resources, km=km, **kwargs).execute()
  File "/opt/hostedtoolcache/Python/3.9.16/x64/lib/python3.9/site-packages/jupyter_core/utils/__init__.py", line 166, in wrapped
    return loop.run_until_complete(inner)
  File "/opt/hostedtoolcache/Python/3.9.16/x64/lib/python3.9/asyncio/base_events.py", line 647, in run_until_complete
    return future.result()
  File "/opt/hostedtoolcache/Python/3.9.16/x64/lib/python3.9/site-packages/nbclient/client.py", line 705, in async_execute
    await self.async_execute_cell(
  File "/opt/hostedtoolcache/Python/3.9.16/x64/lib/python3.9/site-packages/nbclient/client.py", line 1058, in async_execute_cell
    await self._check_raise_for_error(cell, cell_index, exec_reply)
  File "/opt/hostedtoolcache/Python/3.9.16/x64/lib/python3.9/site-packages/nbclient/client.py", line 914, in _check_raise_for_error
    raise CellExecutionError.from_cell_and_msg(cell, exec_reply_content)
nbclient.exceptions.CellExecutionError: An error occurred while executing the following cell:
------------------
from collections import Counter, defaultdict
from itertools import combinations 
import pandas as pd
import numpy as np
import seaborn as sns
import operator
import math
import gensim
import itertools
from sklearn.feature_extraction import DictVectorizer
from sklearn import preprocessing, tree
import matplotlib.pyplot as plt
from sklearn.neural_network import MLPClassifier
from sklearn.svm import SVC
from sklearn.linear_model import LogisticRegression
from sklearn.preprocessing import StandardScaler, MinMaxScaler
from sklearn.preprocessing import LabelEncoder, OneHotEncoder
from sklearn.feature_extraction import DictVectorizer
from sklearn.pipeline import Pipeline
from sklearn.metrics import accuracy_score
from sklearn.model_selection import train_test_split
from sklearn.model_selection import GridSearchCV, ParameterGrid
import collections
import nltk
from sklearn.cluster import KMeans
from sklearn.metrics import silhouette_score
from sklearn.preprocessing import normalize
import warnings
warnings.filterwarnings("ignore")
from sklearn.ensemble import RandomForestClassifier
# from nltk import word_tokenize, tokenize
# nltk.download('punkt')
import plotly.express as px
import statsmodels.api as sm
from sklearn.linear_model import LinearRegression

import scipy.stats as sc
from sklearn.metrics import mean_absolute_error, mean_squared_error

------------------


[0;31m---------------------------------------------------------------------------[0m
[0;31mModuleNotFoundError[0m                       Traceback (most recent call last)
Cell [0;32mIn[1], line 3[0m
[1;32m      1[0m [38;5;28;01mfrom[39;00m [38;5;21;01mcollections[39;00m [38;5;28;01mimport[39;00m Counter, defaultdict
[1;32m      2[0m [38;5;28;01mfrom[39;00m [38;5;21;01mitertools[39;00m [38;5;28;01mimport[39;00m combinations 
[0;32m----> 3[0m [38;5;28;01mimport[39;00m [38;5;21;01mpandas[39;00m [38;5;28;01mas[39;00m [38;5;21;01mpd[39;00m
[1;32m      4[0m [38;5;28;01mimport[39;00m [38;5;21;01mnumpy[39;00m [38;5;28;01mas[39;00m [38;5;21;01mnp[39;00m
[1;32m      5[0m [38;5;28;01mimport[39;00m [38;5;21;01mseaborn[39;00m [38;5;28;01mas[39;00m [38;5;21;01msns[39;00m

[0;31mModuleNotFoundError[0m: No module named 'pandas'

